[2024-12-02T17:40:08.546+0900] {local_task_job_runner.py:123} INFO - ::group::Pre task execution logs
[2024-12-02T17:40:08.556+0900] {taskinstance.py:2613} INFO - Dependencies all met for dep_context=non-requeueable deps ti=<TaskInstance: process_and_upload_json_to_hdfs.save_champion_to_hdfs scheduled__2024-12-02T07:00:00+00:00 [queued]>
[2024-12-02T17:40:08.562+0900] {taskinstance.py:2613} INFO - Dependencies all met for dep_context=requeueable deps ti=<TaskInstance: process_and_upload_json_to_hdfs.save_champion_to_hdfs scheduled__2024-12-02T07:00:00+00:00 [queued]>
[2024-12-02T17:40:08.563+0900] {taskinstance.py:2866} INFO - Starting attempt 2 of 2
[2024-12-02T17:40:08.578+0900] {taskinstance.py:2889} INFO - Executing <Task(BashOperator): save_champion_to_hdfs> on 2024-12-02 07:00:00+00:00
[2024-12-02T17:40:08.581+0900] {standard_task_runner.py:72} INFO - Started process 22423 to run task
[2024-12-02T17:40:08.584+0900] {standard_task_runner.py:104} INFO - Running: ['airflow', 'tasks', 'run', 'process_and_upload_json_to_hdfs', 'save_champion_to_hdfs', 'scheduled__2024-12-02T07:00:00+00:00', '--job-id', '367', '--raw', '--subdir', 'DAGS_FOLDER/data_to_hdfs.py', '--cfg-path', '/tmp/tmpsp_16u7p']
[2024-12-02T17:40:08.586+0900] {standard_task_runner.py:105} INFO - Job 367: Subtask save_champion_to_hdfs
[2024-12-02T17:40:08.619+0900] {task_command.py:467} INFO - Running <TaskInstance: process_and_upload_json_to_hdfs.save_champion_to_hdfs scheduled__2024-12-02T07:00:00+00:00 [running]> on host MN
[2024-12-02T17:40:08.682+0900] {taskinstance.py:3132} INFO - Exporting env vars: AIRFLOW_CTX_DAG_OWNER='airflow' AIRFLOW_CTX_DAG_ID='process_and_upload_json_to_hdfs' AIRFLOW_CTX_TASK_ID='save_champion_to_hdfs' AIRFLOW_CTX_EXECUTION_DATE='2024-12-02T07:00:00+00:00' AIRFLOW_CTX_TRY_NUMBER='2' AIRFLOW_CTX_DAG_RUN_ID='scheduled__2024-12-02T07:00:00+00:00'
[2024-12-02T17:40:08.683+0900] {taskinstance.py:731} INFO - ::endgroup::
[2024-12-02T17:40:08.697+0900] {subprocess.py:78} INFO - Tmp dir root location: /tmp
[2024-12-02T17:40:08.697+0900] {subprocess.py:88} INFO - Running command: ['/usr/bin/bash', '-c', 'for champion_file in /laewon/Riot/output/champion_*.csv; do   hdfs dfs -put -f $champion_file /data/$(basename $champion_file); done']
[2024-12-02T17:40:08.703+0900] {subprocess.py:99} INFO - Output:
[2024-12-02T17:42:54.917+0900] {local_task_job_runner.py:346} WARNING - State of this instance has been externally set to None. Terminating instance.
[2024-12-02T17:42:54.918+0900] {local_task_job_runner.py:245} INFO - ::endgroup::
[2024-12-02T17:42:54.925+0900] {process_utils.py:132} INFO - Sending 15 to group 22423. PIDs of all processes in the group: [22425, 27536, 22423]
[2024-12-02T17:42:54.925+0900] {process_utils.py:87} INFO - Sending the signal 15 to group 22423
[2024-12-02T17:42:54.925+0900] {taskinstance.py:3093} ERROR - Received SIGTERM. Terminating subprocesses.
[2024-12-02T17:42:54.926+0900] {subprocess.py:117} INFO - Sending SIGTERM signal to process group
[2024-12-02T17:42:54.934+0900] {taskinstance.py:3311} ERROR - Task failed with exception
Traceback (most recent call last):
  File "/laewon/airflow_test/py_venv/lib/python3.8/site-packages/airflow/models/taskinstance.py", line 767, in _execute_task
    result = _execute_callable(context=context, **execute_callable_kwargs)
  File "/laewon/airflow_test/py_venv/lib/python3.8/site-packages/airflow/models/taskinstance.py", line 733, in _execute_callable
    return ExecutionCallableRunner(
  File "/laewon/airflow_test/py_venv/lib/python3.8/site-packages/airflow/utils/operator_helpers.py", line 252, in run
    return self.func(*args, **kwargs)
  File "/laewon/airflow_test/py_venv/lib/python3.8/site-packages/airflow/models/baseoperator.py", line 417, in wrapper
    return func(self, *args, **kwargs)
  File "/laewon/airflow_test/py_venv/lib/python3.8/site-packages/airflow/operators/bash.py", line 257, in execute
    result = self._run_inline_command(bash_path=bash_path, env=env)
  File "/laewon/airflow_test/py_venv/lib/python3.8/site-packages/airflow/operators/bash.py", line 284, in _run_inline_command
    return self.subprocess_hook.run_command(
  File "/laewon/airflow_test/py_venv/lib/python3.8/site-packages/airflow/hooks/subprocess.py", line 104, in run_command
    for raw_line in iter(self.sub_process.stdout.readline, b""):
  File "/laewon/airflow_test/py_venv/lib/python3.8/site-packages/airflow/models/taskinstance.py", line 3095, in signal_handler
    raise AirflowTaskTerminated("Task received SIGTERM signal")
airflow.exceptions.AirflowTaskTerminated: Task received SIGTERM signal
[2024-12-02T17:42:54.936+0900] {taskinstance.py:1225} INFO - Marking task as FAILED. dag_id=process_and_upload_json_to_hdfs, task_id=save_champion_to_hdfs, run_id=scheduled__2024-12-02T07:00:00+00:00, execution_date=20241202T070000, start_date=20241202T084008, end_date=20241202T084254
[2024-12-02T17:42:54.946+0900] {taskinstance.py:340} INFO - ::group::Post task execution logs
[2024-12-02T17:42:54.947+0900] {standard_task_runner.py:124} ERROR - Failed to execute job 367 for task save_champion_to_hdfs ((sqlite3.IntegrityError) FOREIGN KEY constraint failed
[SQL: INSERT INTO task_fail (task_id, dag_id, run_id, map_index, start_date, end_date, duration) VALUES (?, ?, ?, ?, ?, ?, ?)]
[parameters: ('save_champion_to_hdfs', 'process_and_upload_json_to_hdfs', 'scheduled__2024-12-02T07:00:00+00:00', -1, '2024-12-02 08:40:08.556571', '2024-12-02 08:42:54.936185', 166)]
(Background on this error at: https://sqlalche.me/e/14/gkpj); 22423)
Traceback (most recent call last):
  File "/laewon/airflow_test/py_venv/lib/python3.8/site-packages/airflow/models/taskinstance.py", line 273, in _run_raw_task
    TaskInstance._execute_task_with_callbacks(
  File "/laewon/airflow_test/py_venv/lib/python3.8/site-packages/airflow/models/taskinstance.py", line 3159, in _execute_task_with_callbacks
    result = self._execute_task(context, task_orig)
  File "/laewon/airflow_test/py_venv/lib/python3.8/site-packages/airflow/models/taskinstance.py", line 3183, in _execute_task
    return _execute_task(self, context, task_orig)
  File "/laewon/airflow_test/py_venv/lib/python3.8/site-packages/airflow/models/taskinstance.py", line 767, in _execute_task
    result = _execute_callable(context=context, **execute_callable_kwargs)
  File "/laewon/airflow_test/py_venv/lib/python3.8/site-packages/airflow/models/taskinstance.py", line 733, in _execute_callable
    return ExecutionCallableRunner(
  File "/laewon/airflow_test/py_venv/lib/python3.8/site-packages/airflow/utils/operator_helpers.py", line 252, in run
    return self.func(*args, **kwargs)
  File "/laewon/airflow_test/py_venv/lib/python3.8/site-packages/airflow/models/baseoperator.py", line 417, in wrapper
    return func(self, *args, **kwargs)
  File "/laewon/airflow_test/py_venv/lib/python3.8/site-packages/airflow/operators/bash.py", line 257, in execute
    result = self._run_inline_command(bash_path=bash_path, env=env)
  File "/laewon/airflow_test/py_venv/lib/python3.8/site-packages/airflow/operators/bash.py", line 284, in _run_inline_command
    return self.subprocess_hook.run_command(
  File "/laewon/airflow_test/py_venv/lib/python3.8/site-packages/airflow/hooks/subprocess.py", line 104, in run_command
    for raw_line in iter(self.sub_process.stdout.readline, b""):
  File "/laewon/airflow_test/py_venv/lib/python3.8/site-packages/airflow/models/taskinstance.py", line 3095, in signal_handler
    raise AirflowTaskTerminated("Task received SIGTERM signal")
airflow.exceptions.AirflowTaskTerminated: Task received SIGTERM signal

During handling of the above exception, another exception occurred:

Traceback (most recent call last):
  File "/laewon/airflow_test/py_venv/lib/python3.8/site-packages/sqlalchemy/engine/base.py", line 1910, in _execute_context
    self.dialect.do_execute(
  File "/laewon/airflow_test/py_venv/lib/python3.8/site-packages/sqlalchemy/engine/default.py", line 736, in do_execute
    cursor.execute(statement, parameters)
sqlite3.IntegrityError: FOREIGN KEY constraint failed

The above exception was the direct cause of the following exception:

Traceback (most recent call last):
  File "/laewon/airflow_test/py_venv/lib/python3.8/site-packages/airflow/task/task_runner/standard_task_runner.py", line 117, in _start_by_fork
    ret = args.func(args, dag=self.dag)
  File "/laewon/airflow_test/py_venv/lib/python3.8/site-packages/airflow/cli/cli_config.py", line 49, in command
    return func(*args, **kwargs)
  File "/laewon/airflow_test/py_venv/lib/python3.8/site-packages/airflow/utils/cli.py", line 116, in wrapper
    return f(*args, **kwargs)
  File "/laewon/airflow_test/py_venv/lib/python3.8/site-packages/airflow/cli/commands/task_command.py", line 483, in task_run
    task_return_code = _run_task_by_selected_method(args, _dag, ti)
  File "/laewon/airflow_test/py_venv/lib/python3.8/site-packages/airflow/cli/commands/task_command.py", line 256, in _run_task_by_selected_method
    return _run_raw_task(args, ti)
  File "/laewon/airflow_test/py_venv/lib/python3.8/site-packages/airflow/cli/commands/task_command.py", line 341, in _run_raw_task
    return ti._run_raw_task(
  File "/laewon/airflow_test/py_venv/lib/python3.8/site-packages/airflow/utils/session.py", line 97, in wrapper
    return func(*args, session=session, **kwargs)
  File "/laewon/airflow_test/py_venv/lib/python3.8/site-packages/airflow/models/taskinstance.py", line 3005, in _run_raw_task
    return _run_raw_task(
  File "/laewon/airflow_test/py_venv/lib/python3.8/site-packages/airflow/models/taskinstance.py", line 327, in _run_raw_task
    ti.handle_failure(e, test_mode, context, session=session)
  File "/laewon/airflow_test/py_venv/lib/python3.8/site-packages/airflow/utils/session.py", line 94, in wrapper
    return func(*args, **kwargs)
  File "/laewon/airflow_test/py_venv/lib/python3.8/site-packages/airflow/models/taskinstance.py", line 3428, in handle_failure
    _handle_failure(
  File "/laewon/airflow_test/py_venv/lib/python3.8/site-packages/airflow/utils/session.py", line 94, in wrapper
    return func(*args, **kwargs)
  File "/laewon/airflow_test/py_venv/lib/python3.8/site-packages/airflow/api_internal/internal_api_call.py", line 166, in wrapper
    return func(*args, **kwargs)
  File "/laewon/airflow_test/py_venv/lib/python3.8/site-packages/airflow/models/taskinstance.py", line 1243, in _handle_failure
    TaskInstance.save_to_db(failure_context["ti"], session)
  File "/laewon/airflow_test/py_venv/lib/python3.8/site-packages/airflow/api_internal/internal_api_call.py", line 166, in wrapper
    return func(*args, **kwargs)
  File "/laewon/airflow_test/py_venv/lib/python3.8/site-packages/airflow/utils/session.py", line 94, in wrapper
    return func(*args, **kwargs)
  File "/laewon/airflow_test/py_venv/lib/python3.8/site-packages/airflow/models/taskinstance.py", line 3400, in save_to_db
    session.flush()
  File "/laewon/airflow_test/py_venv/lib/python3.8/site-packages/sqlalchemy/orm/session.py", line 3449, in flush
    self._flush(objects)
  File "/laewon/airflow_test/py_venv/lib/python3.8/site-packages/sqlalchemy/orm/session.py", line 3589, in _flush
    transaction.rollback(_capture_exception=True)
  File "/laewon/airflow_test/py_venv/lib/python3.8/site-packages/sqlalchemy/util/langhelpers.py", line 70, in __exit__
    compat.raise_(
  File "/laewon/airflow_test/py_venv/lib/python3.8/site-packages/sqlalchemy/util/compat.py", line 211, in raise_
    raise exception
  File "/laewon/airflow_test/py_venv/lib/python3.8/site-packages/sqlalchemy/orm/session.py", line 3549, in _flush
    flush_context.execute()
  File "/laewon/airflow_test/py_venv/lib/python3.8/site-packages/sqlalchemy/orm/unitofwork.py", line 456, in execute
    rec.execute(self)
  File "/laewon/airflow_test/py_venv/lib/python3.8/site-packages/sqlalchemy/orm/unitofwork.py", line 630, in execute
    util.preloaded.orm_persistence.save_obj(
  File "/laewon/airflow_test/py_venv/lib/python3.8/site-packages/sqlalchemy/orm/persistence.py", line 245, in save_obj
    _emit_insert_statements(
  File "/laewon/airflow_test/py_venv/lib/python3.8/site-packages/sqlalchemy/orm/persistence.py", line 1238, in _emit_insert_statements
    result = connection._execute_20(
  File "/laewon/airflow_test/py_venv/lib/python3.8/site-packages/sqlalchemy/engine/base.py", line 1710, in _execute_20
    return meth(self, args_10style, kwargs_10style, execution_options)
  File "/laewon/airflow_test/py_venv/lib/python3.8/site-packages/sqlalchemy/sql/elements.py", line 334, in _execute_on_connection
    return connection._execute_clauseelement(
  File "/laewon/airflow_test/py_venv/lib/python3.8/site-packages/sqlalchemy/engine/base.py", line 1577, in _execute_clauseelement
    ret = self._execute_context(
  File "/laewon/airflow_test/py_venv/lib/python3.8/site-packages/sqlalchemy/engine/base.py", line 1953, in _execute_context
    self._handle_dbapi_exception(
  File "/laewon/airflow_test/py_venv/lib/python3.8/site-packages/sqlalchemy/engine/base.py", line 2134, in _handle_dbapi_exception
    util.raise_(
  File "/laewon/airflow_test/py_venv/lib/python3.8/site-packages/sqlalchemy/util/compat.py", line 211, in raise_
    raise exception
  File "/laewon/airflow_test/py_venv/lib/python3.8/site-packages/sqlalchemy/engine/base.py", line 1910, in _execute_context
    self.dialect.do_execute(
  File "/laewon/airflow_test/py_venv/lib/python3.8/site-packages/sqlalchemy/engine/default.py", line 736, in do_execute
    cursor.execute(statement, parameters)
sqlalchemy.exc.IntegrityError: (sqlite3.IntegrityError) FOREIGN KEY constraint failed
[SQL: INSERT INTO task_fail (task_id, dag_id, run_id, map_index, start_date, end_date, duration) VALUES (?, ?, ?, ?, ?, ?, ?)]
[parameters: ('save_champion_to_hdfs', 'process_and_upload_json_to_hdfs', 'scheduled__2024-12-02T07:00:00+00:00', -1, '2024-12-02 08:40:08.556571', '2024-12-02 08:42:54.936185', 166)]
(Background on this error at: https://sqlalche.me/e/14/gkpj)
[2024-12-02T17:42:55.218+0900] {process_utils.py:80} INFO - Process psutil.Process(pid=27536, status='terminated', started='17:42:52') (27536) terminated with exit code None
[2024-12-02T17:42:55.219+0900] {process_utils.py:80} INFO - Process psutil.Process(pid=22425, status='terminated', started='17:40:08') (22425) terminated with exit code None
[2024-12-02T17:42:55.219+0900] {process_utils.py:80} INFO - Process psutil.Process(pid=22423, status='terminated', exitcode=1, started='17:40:08') (22423) terminated with exit code 1
